Internal Server Error: /1/0
Traceback (most recent call last):
  File "/home/aucky/.local/lib/python3.8/site-packages/django/core/handlers/exception.py", line 55, in inner
    response = get_response(request)
  File "/home/aucky/.local/lib/python3.8/site-packages/django/core/handlers/base.py", line 197, in _get_response
    response = wrapped_callback(request, *callback_args, **callback_kwargs)
  File "/home/aucky/.local/lib/python3.8/site-packages/django/contrib/auth/decorators.py", line 23, in _wrapped_view
    return view_func(request, *args, **kwargs)
  File "/mnt/c/Users/m_auc/Downloads/quiz-fivetival/src/quizfivetival/quiz/views.py", line 34, in quiz_view
    questions = q[int(soal)]
  File "/home/aucky/.local/lib/python3.8/site-packages/django/db/models/query.py", line 362, in __getitem__
    return qs._result_cache[0]
IndexError: list index out of range
"GET /1/0 HTTP/1.1" 500 145
"GET /admin/quiz/question/ HTTP/1.1" 200 6691
"GET /admin/jsi18n/ HTTP/1.1" 200 3343
"GET /admin/quiz/question/add/ HTTP/1.1" 200 16908
"GET /static/admin/js/inlines.fb1617228dbe.js HTTP/1.1" 200 3630
"GET /admin/jsi18n/ HTTP/1.1" 200 3343
"GET /static/admin/img/inline-delete.fec1b761f254.svg HTTP/1.1" 200 293
"POST /admin/quiz/question/add/ HTTP/1.1" 302 0
"GET /admin/quiz/question/ HTTP/1.1" 200 8039
"GET /admin/jsi18n/ HTTP/1.1" 200 3343
Exception while resolving variable 'key' in template 'quizes/quiz.html'.
Traceback (most recent call last):
  File "/home/aucky/.local/lib/python3.8/site-packages/django/template/base.py", line 875, in _resolve_lookup
    current = current[bit]
  File "/home/aucky/.local/lib/python3.8/site-packages/django/template/context.py", line 83, in __getitem__
    raise KeyError(key)
KeyError: 'key'

During handling of the above exception, another exception occurred:

Traceback (most recent call last):
  File "/home/aucky/.local/lib/python3.8/site-packages/django/template/base.py", line 881, in _resolve_lookup
    if isinstance(current, BaseContext) and getattr(
AttributeError: type object 'RequestContext' has no attribute 'key'

During handling of the above exception, another exception occurred:

Traceback (most recent call last):
  File "/home/aucky/.local/lib/python3.8/site-packages/django/template/base.py", line 891, in _resolve_lookup
    current = current[int(bit)]
ValueError: invalid literal for int() with base 10: 'key'

During handling of the above exception, another exception occurred:

Traceback (most recent call last):
  File "/home/aucky/.local/lib/python3.8/site-packages/django/template/base.py", line 898, in _resolve_lookup
    raise VariableDoesNotExist(
django.template.base.VariableDoesNotExist: Failed lookup for key [key] in [{'True': True, 'False': False, 'None': None}, {'csrf_token': <SimpleLazyObject: 'duKyUiQGO11Ec11BJlOvxQ1K6TMr7l9N3UjVq1trZA8IuA1MSKa9apAlevZvFhvl'>, 'request': <WSGIRequest: GET '/1/0'>, 'user': <SimpleLazyObject: <User: admin>>, 'perms': PermWrapper(<SimpleLazyObject: <User: admin>>), 'messages': <FallbackStorage: request=<WSGIRequest: GET '/1/0'>>, 'DEFAULT_MESSAGE_LEVELS': {'DEBUG': 10, 'INFO': 20, 'SUCCESS': 25, 'WARNING': 30, 'ERROR': 40}}, {}, {'obj': <Quiz: English Quiz-Ok>, 'bis': {'1': False}, 'pk': 1, 'soal': <Question: kodok>, 'a': None, 'ans': [<Answer: question: kodok, answer: sapi, correct: True>, <Answer: question: kodok, answer: a, correct: False>, <Answer: question: kodok, answer: b, correct: False>], 'jumsol': 1}]
Exception while resolving variable 'key' in template 'quizes/quiz.html'.
Traceback (most recent call last):
  File "/home/aucky/.local/lib/python3.8/site-packages/django/template/base.py", line 875, in _resolve_lookup
    current = current[bit]
  File "/home/aucky/.local/lib/python3.8/site-packages/django/template/context.py", line 83, in __getitem__
    raise KeyError(key)
KeyError: 'key'

During handling of the above exception, another exception occurred:

Traceback (most recent call last):
  File "/home/aucky/.local/lib/python3.8/site-packages/django/template/base.py", line 881, in _resolve_lookup
    if isinstance(current, BaseContext) and getattr(
AttributeError: type object 'RequestContext' has no attribute 'key'

During handling of the above exception, another exception occurred:

Traceback (most recent call last):
  File "/home/aucky/.local/lib/python3.8/site-packages/django/template/base.py", line 891, in _resolve_lookup
    current = current[int(bit)]
ValueError: invalid literal for int() with base 10: 'key'

During handling of the above exception, another exception occurred:

Traceback (most recent call last):
  File "/home/aucky/.local/lib/python3.8/site-packages/django/template/base.py", line 898, in _resolve_lookup
    raise VariableDoesNotExist(
django.template.base.VariableDoesNotExist: Failed lookup for key [key] in [{'True': True, 'False': False, 'None': None}, {'csrf_token': <SimpleLazyObject: 'duKyUiQGO11Ec11BJlOvxQ1K6TMr7l9N3UjVq1trZA8IuA1MSKa9apAlevZvFhvl'>, 'request': <WSGIRequest: GET '/1/0'>, 'user': <SimpleLazyObject: <User: admin>>, 'perms': PermWrapper(<SimpleLazyObject: <User: admin>>), 'messages': <FallbackStorage: request=<WSGIRequest: GET '/1/0'>>, 'DEFAULT_MESSAGE_LEVELS': {'DEBUG': 10, 'INFO': 20, 'SUCCESS': 25, 'WARNING': 30, 'ERROR': 40}}, {}, {'obj': <Quiz: English Quiz-Ok>, 'bis': {'1': False}, 'pk': 1, 'soal': <Question: kodok>, 'a': None, 'ans': [<Answer: question: kodok, answer: sapi, correct: True>, <Answer: question: kodok, answer: a, correct: False>, <Answer: question: kodok, answer: b, correct: False>], 'jumsol': 1}]
"GET /1/0 HTTP/1.1" 200 13739
Internal Server Error: /1/0data
Traceback (most recent call last):
  File "/home/aucky/.local/lib/python3.8/site-packages/django/core/handlers/exception.py", line 55, in inner
    response = get_response(request)
  File "/home/aucky/.local/lib/python3.8/site-packages/django/core/handlers/base.py", line 197, in _get_response
    response = wrapped_callback(request, *callback_args, **callback_kwargs)
  File "/home/aucky/.local/lib/python3.8/site-packages/django/contrib/auth/decorators.py", line 23, in _wrapped_view
    return view_func(request, *args, **kwargs)
  File "/mnt/c/Users/m_auc/Downloads/quiz-fivetival/src/quizfivetival/quiz/views.py", line 34, in quiz_view
    questions = q[int(soal)]
ValueError: invalid literal for int() with base 10: '0data'
"GET /1/0data HTTP/1.1" 500 145
"POST /1/0 HTTP/1.1" 302 0
Exception while resolving variable 'key' in template 'quizes/quiz.html'.
Traceback (most recent call last):
  File "/home/aucky/.local/lib/python3.8/site-packages/django/template/base.py", line 875, in _resolve_lookup
    current = current[bit]
  File "/home/aucky/.local/lib/python3.8/site-packages/django/template/context.py", line 83, in __getitem__
    raise KeyError(key)
KeyError: 'key'

During handling of the above exception, another exception occurred:

Traceback (most recent call last):
  File "/home/aucky/.local/lib/python3.8/site-packages/django/template/base.py", line 881, in _resolve_lookup
    if isinstance(current, BaseContext) and getattr(
AttributeError: type object 'RequestContext' has no attribute 'key'

During handling of the above exception, another exception occurred:

Traceback (most recent call last):
  File "/home/aucky/.local/lib/python3.8/site-packages/django/template/base.py", line 891, in _resolve_lookup
    current = current[int(bit)]
ValueError: invalid literal for int() with base 10: 'key'

During handling of the above exception, another exception occurred:

Traceback (most recent call last):
  File "/home/aucky/.local/lib/python3.8/site-packages/django/template/base.py", line 898, in _resolve_lookup
    raise VariableDoesNotExist(
django.template.base.VariableDoesNotExist: Failed lookup for key [key] in [{'True': True, 'False': False, 'None': None}, {'csrf_token': <SimpleLazyObject: 'MdGX2dBV3zJFr3IP4TDzWMIoVU7fwTEYCDfkyWeGe8QJJCI0diZdzlhZ3wkj4P0w'>, 'request': <WSGIRequest: GET '/1/0'>, 'user': <SimpleLazyObject: <User: admin>>, 'perms': PermWrapper(<SimpleLazyObject: <User: admin>>), 'messages': <FallbackStorage: request=<WSGIRequest: GET '/1/0'>>, 'DEFAULT_MESSAGE_LEVELS': {'DEBUG': 10, 'INFO': 20, 'SUCCESS': 25, 'WARNING': 30, 'ERROR': 40}}, {}, {'obj': <Quiz: English Quiz-Ok>, 'bis': {'1': True}, 'pk': 1, 'soal': <Question: kodok>, 'a': <AnswerAnggota: kodok, None>, 'ans': [<Answer: question: kodok, answer: sapi, correct: True>, <Answer: question: kodok, answer: a, correct: False>, <Answer: question: kodok, answer: b, correct: False>], 'jumsol': 1}]
Exception while resolving variable 'key' in template 'quizes/quiz.html'.
Traceback (most recent call last):
  File "/home/aucky/.local/lib/python3.8/site-packages/django/template/base.py", line 875, in _resolve_lookup
    current = current[bit]
  File "/home/aucky/.local/lib/python3.8/site-packages/django/template/context.py", line 83, in __getitem__
    raise KeyError(key)
KeyError: 'key'

During handling of the above exception, another exception occurred:

Traceback (most recent call last):
  File "/home/aucky/.local/lib/python3.8/site-packages/django/template/base.py", line 881, in _resolve_lookup
    if isinstance(current, BaseContext) and getattr(
AttributeError: type object 'RequestContext' has no attribute 'key'

During handling of the above exception, another exception occurred:

Traceback (most recent call last):
  File "/home/aucky/.local/lib/python3.8/site-packages/django/template/base.py", line 891, in _resolve_lookup
    current = current[int(bit)]
ValueError: invalid literal for int() with base 10: 'key'

During handling of the above exception, another exception occurred:

Traceback (most recent call last):
  File "/home/aucky/.local/lib/python3.8/site-packages/django/template/base.py", line 898, in _resolve_lookup
    raise VariableDoesNotExist(
django.template.base.VariableDoesNotExist: Failed lookup for key [key] in [{'True': True, 'False': False, 'None': None}, {'csrf_token': <SimpleLazyObject: 'MdGX2dBV3zJFr3IP4TDzWMIoVU7fwTEYCDfkyWeGe8QJJCI0diZdzlhZ3wkj4P0w'>, 'request': <WSGIRequest: GET '/1/0'>, 'user': <SimpleLazyObject: <User: admin>>, 'perms': PermWrapper(<SimpleLazyObject: <User: admin>>), 'messages': <FallbackStorage: request=<WSGIRequest: GET '/1/0'>>, 'DEFAULT_MESSAGE_LEVELS': {'DEBUG': 10, 'INFO': 20, 'SUCCESS': 25, 'WARNING': 30, 'ERROR': 40}}, {}, {'obj': <Quiz: English Quiz-Ok>, 'bis': {'1': True}, 'pk': 1, 'soal': <Question: kodok>, 'a': <AnswerAnggota: kodok, None>, 'ans': [<Answer: question: kodok, answer: sapi, correct: True>, <Answer: question: kodok, answer: a, correct: False>, <Answer: question: kodok, answer: b, correct: False>], 'jumsol': 1}]
"GET /1/0 HTTP/1.1" 200 13798
Internal Server Error: /1/0data
Traceback (most recent call last):
  File "/home/aucky/.local/lib/python3.8/site-packages/django/core/handlers/exception.py", line 55, in inner
    response = get_response(request)
  File "/home/aucky/.local/lib/python3.8/site-packages/django/core/handlers/base.py", line 197, in _get_response
    response = wrapped_callback(request, *callback_args, **callback_kwargs)
  File "/home/aucky/.local/lib/python3.8/site-packages/django/contrib/auth/decorators.py", line 23, in _wrapped_view
    return view_func(request, *args, **kwargs)
  File "/mnt/c/Users/m_auc/Downloads/quiz-fivetival/src/quizfivetival/quiz/views.py", line 34, in quiz_view
    questions = q[int(soal)]
ValueError: invalid literal for int() with base 10: '0data'
"GET /1/0data HTTP/1.1" 500 145
Exception while resolving variable 'time' in template 'quizes/main.html'.
Traceback (most recent call last):
  File "/home/aucky/.local/lib/python3.8/site-packages/django/template/base.py", line 875, in _resolve_lookup
    current = current[bit]
TypeError: 'Quiz' object is not subscriptable

During handling of the above exception, another exception occurred:

Traceback (most recent call last):
  File "/home/aucky/.local/lib/python3.8/site-packages/django/template/base.py", line 885, in _resolve_lookup
    current = getattr(current, bit)
AttributeError: 'Quiz' object has no attribute 'time'

During handling of the above exception, another exception occurred:

Traceback (most recent call last):
  File "/home/aucky/.local/lib/python3.8/site-packages/django/template/base.py", line 891, in _resolve_lookup
    current = current[int(bit)]
ValueError: invalid literal for int() with base 10: 'time'

During handling of the above exception, another exception occurred:

Traceback (most recent call last):
  File "/home/aucky/.local/lib/python3.8/site-packages/django/template/base.py", line 898, in _resolve_lookup
    raise VariableDoesNotExist(
django.template.base.VariableDoesNotExist: Failed lookup for key [time] in <Quiz: English Quiz-Ok>
"GET / HTTP/1.1" 200 4145
Exception while resolving variable 'key' in template 'quizes/quiz.html'.
Traceback (most recent call last):
  File "/home/aucky/.local/lib/python3.8/site-packages/django/template/base.py", line 875, in _resolve_lookup
    current = current[bit]
  File "/home/aucky/.local/lib/python3.8/site-packages/django/template/context.py", line 83, in __getitem__
    raise KeyError(key)
KeyError: 'key'

During handling of the above exception, another exception occurred:

Traceback (most recent call last):
  File "/home/aucky/.local/lib/python3.8/site-packages/django/template/base.py", line 881, in _resolve_lookup
    if isinstance(current, BaseContext) and getattr(
AttributeError: type object 'RequestContext' has no attribute 'key'

During handling of the above exception, another exception occurred:

Traceback (most recent call last):
  File "/home/aucky/.local/lib/python3.8/site-packages/django/template/base.py", line 891, in _resolve_lookup
    current = current[int(bit)]
ValueError: invalid literal for int() with base 10: 'key'

During handling of the above exception, another exception occurred:

Traceback (most recent call last):
  File "/home/aucky/.local/lib/python3.8/site-packages/django/template/base.py", line 898, in _resolve_lookup
    raise VariableDoesNotExist(
django.template.base.VariableDoesNotExist: Failed lookup for key [key] in [{'True': True, 'False': False, 'None': None}, {'csrf_token': <SimpleLazyObject: 'ngNqwvml6CZGlTw6GRl2A49M0IWSknutdGmN2eZ6hb6KDswhPgHGdDIn8k9WSjQ1'>, 'request': <WSGIRequest: GET '/1/0'>, 'user': <SimpleLazyObject: <User: admin>>, 'perms': PermWrapper(<SimpleLazyObject: <User: admin>>), 'messages': <FallbackStorage: request=<WSGIRequest: GET '/1/0'>>, 'DEFAULT_MESSAGE_LEVELS': {'DEBUG': 10, 'INFO': 20, 'SUCCESS': 25, 'WARNING': 30, 'ERROR': 40}}, {}, {'obj': <Quiz: English Quiz-Ok>, 'bis': {'1': True}, 'pk': 1, 'soal': <Question: kodok>, 'a': <AnswerAnggota: kodok, None>, 'ans': [<Answer: question: kodok, answer: sapi, correct: True>, <Answer: question: kodok, answer: a, correct: False>, <Answer: question: kodok, answer: b, correct: False>], 'jumsol': 1}]
Exception while resolving variable 'key' in template 'quizes/quiz.html'.
Traceback (most recent call last):
  File "/home/aucky/.local/lib/python3.8/site-packages/django/template/base.py", line 875, in _resolve_lookup
    current = current[bit]
  File "/home/aucky/.local/lib/python3.8/site-packages/django/template/context.py", line 83, in __getitem__
    raise KeyError(key)
KeyError: 'key'

During handling of the above exception, another exception occurred:

Traceback (most recent call last):
  File "/home/aucky/.local/lib/python3.8/site-packages/django/template/base.py", line 881, in _resolve_lookup
    if isinstance(current, BaseContext) and getattr(
AttributeError: type object 'RequestContext' has no attribute 'key'

During handling of the above exception, another exception occurred:

Traceback (most recent call last):
  File "/home/aucky/.local/lib/python3.8/site-packages/django/template/base.py", line 891, in _resolve_lookup
    current = current[int(bit)]
ValueError: invalid literal for int() with base 10: 'key'

During handling of the above exception, another exception occurred:

Traceback (most recent call last):
  File "/home/aucky/.local/lib/python3.8/site-packages/django/template/base.py", line 898, in _resolve_lookup
    raise VariableDoesNotExist(
django.template.base.VariableDoesNotExist: Failed lookup for key [key] in [{'True': True, 'False': False, 'None': None}, {'csrf_token': <SimpleLazyObject: 'ngNqwvml6CZGlTw6GRl2A49M0IWSknutdGmN2eZ6hb6KDswhPgHGdDIn8k9WSjQ1'>, 'request': <WSGIRequest: GET '/1/0'>, 'user': <SimpleLazyObject: <User: admin>>, 'perms': PermWrapper(<SimpleLazyObject: <User: admin>>), 'messages': <FallbackStorage: request=<WSGIRequest: GET '/1/0'>>, 'DEFAULT_MESSAGE_LEVELS': {'DEBUG': 10, 'INFO': 20, 'SUCCESS': 25, 'WARNING': 30, 'ERROR': 40}}, {}, {'obj': <Quiz: English Quiz-Ok>, 'bis': {'1': True}, 'pk': 1, 'soal': <Question: kodok>, 'a': <AnswerAnggota: kodok, None>, 'ans': [<Answer: question: kodok, answer: sapi, correct: True>, <Answer: question: kodok, answer: a, correct: False>, <Answer: question: kodok, answer: b, correct: False>], 'jumsol': 1}]
"GET /1/0 HTTP/1.1" 200 13798
Internal Server Error: /1/0data
Traceback (most recent call last):
  File "/home/aucky/.local/lib/python3.8/site-packages/django/core/handlers/exception.py", line 55, in inner
    response = get_response(request)
  File "/home/aucky/.local/lib/python3.8/site-packages/django/core/handlers/base.py", line 197, in _get_response
    response = wrapped_callback(request, *callback_args, **callback_kwargs)
  File "/home/aucky/.local/lib/python3.8/site-packages/django/contrib/auth/decorators.py", line 23, in _wrapped_view
    return view_func(request, *args, **kwargs)
  File "/mnt/c/Users/m_auc/Downloads/quiz-fivetival/src/quizfivetival/quiz/views.py", line 34, in quiz_view
    questions = q[int(soal)]
ValueError: invalid literal for int() with base 10: '0data'
"GET /1/0data HTTP/1.1" 500 145
